
exception TestError();

import void g();

void f() {
	{
		scope(success) {
			throw TestError();
		}
	}
	g();
}
