
exception TestError();

void f() {
	{
		scope(success) {
			throw TestError();
		}
		scope(success) {
			throw TestError();
		}
	}
}
