
exception TestError();

import void g();

void f() {
	scope(success) {
		g();
	}
	throw TestError();
}
